<?xml version="1.0" encoding="utf-8"?>
<!-- =================================================================================== -->
<!-- |    This document was autogenerated by xacro from arm_schunk.urdf.xacro          | -->
<!-- |    EDITING THIS FILE BY HAND IS NOT RECOMMENDED                                 | -->
<!-- =================================================================================== -->
<robot name="teodor_2lwa4d" xmlns:xacro="http://www.ros.org/wiki/xacro">
  <material name="Schunk/LightGrey">
    <color rgba="0.7 0.7 0.7 1.0"/>
  </material>
  <material name="Schunk/DarkGrey">
    <color rgba="0.4 0.4 0.4 1.0"/>
  </material>
  <material name="Schunk/Black">
    <color rgba="0.0 0.0 0.0 1.0"/>
  </material>
  <material name="Schunk/DarkGolden">
    <color rgba="0.4 0.4 0.3 1.0"/>
  </material>
  <material name="Schunk/Blue">
    <color rgba="0.0 0.0 0.8 1.0"/>
  </material>
  <link name="world"/>
  <joint name="world_joint" type="fixed">
    <parent link="world"/>
    <child link="base_link"/>
    <origin rpy="0 0 0" xyz="0. 0. 0."/>
  </joint>
  <link name="base_link">
    <visual>
      <origin rpy="0 0 0" xyz="0 0 0"/>
      <geometry>
        <box size="0.01 0.01 0.01"/>
      </geometry>
    </visual>
    <collision>
      <origin rpy="0 0 0" xyz="0 0 0"/>
      <geometry>
        <box size="0.01 0.01 0.01"/>
      </geometry>
    </collision>
  </link>
  <!-- arm mount -->
  <joint name="mount_joint" type="fixed">
    <parent link="base_link"/>
    <child link="mount_link"/>
    <origin rpy="0 0 0" xyz="0. 0. 0."/>
  </joint>
  <link name="mount_link">
    <visual>
      <origin rpy="0 1.57 0" xyz="0 0 0"/>
      <geometry>
        <box size="0.02 0.6 0.6"/>
      </geometry>
      <material name="Schunk/LightGrey">
        <color rgba="0.7 0.7 0.7 1"/>
      </material>
    </visual>
    <collision>
      <origin rpy="0 0 0" xyz="-0.0215 0.0 -0.01"/>
      <geometry>
        <box size="0.043 0.6 0.21"/>
      </geometry>
    </collision>
  </link>
  <!-- joint between base_link and lwa4p_extended_connector_link -->
  <joint name="right_arm_podest_joint" type="fixed">
    <origin rpy="0 0 0" xyz="0 0 0"/>
    <parent link="mount_link"/>
    <child link="right_arm_podest_link"/>
  </joint>
  <link name="right_arm_podest_link">
    <inertial>
      <mass value="0.01"/>
      <origin xyz="0 0 0"/>
      <inertia ixx="0.001" ixy="0.0" ixz="0.0" iyy="0.001" iyz="0.0" izz="0.001"/>
    </inertial>
    <visual>
      <geometry>
        <mesh filename="package://lwa4d/arm_podest_link.stl"/>
      </geometry>
      <material name="Schunk/LightGrey"/>
    </visual>
    <collision>
      <geometry>
        <mesh filename="package://lwa4d/arm_podest_link.stl"/>
      </geometry>
    </collision>
  </link>
  <joint name="right_arm_base_joint" type="fixed">
    <origin rpy="0 0 0" xyz="0 0 0.140"/>
    <parent link="right_arm_podest_link"/>
    <child link="right_arm_base_link"/>
  </joint>
  <link name="right_arm_base_link">
    <inertial>
      <mass value="0.01"/>
      <origin xyz="0 0 0"/>
      <inertia ixx="0.001" ixy="0.0" ixz="0.0" iyy="0.001" iyz="0.0" izz="0.001"/>
    </inertial>
  </link>
  <!-- joint between arm_base_link and arm_1_link -->
  <joint name="right_arm_1_joint" type="revolute">
    <origin rpy="0 0 0" xyz="0 0 0"/>
    <parent link="right_arm_base_link"/>
    <child link="right_arm_1_link"/>
    <axis xyz="0 0 -1"/>
    <limit effort="2160" lower="-3.12159265359" upper="3.12159265359" velocity="0.43633"/>
  </joint>
  <link name="right_arm_1_link">
    <inertial>
      <mass value="0.01"/>
      <origin xyz="0 0 0"/>
      <inertia ixx="0.001" ixy="0.0" ixz="0.0" iyy="0.001" iyz="0.0" izz="0.001"/>
    </inertial>
    <!--
      <xacro:cylinder_inertial radius="0.06" length="0.150" mass="3.6">
          <origin xyz="0 0 0.02" rpy="0 0 0"/>
      </xacro:cylinder_inertial>
-->
    <visual>
      <geometry>
        <mesh filename="package://lwa4d/arm_1_link.stl"/>
      </geometry>
      <material name="Schunk/LightGrey"/>
    </visual>
    <collision>
      <geometry>
        <mesh filename="package://lwa4d/arm_1_link.stl"/>
      </geometry>
    </collision>
  </link>
  <!-- joint between arm_1_link and arm_2_link -->
  <joint name="right_arm_2_joint" type="revolute">
    <origin rpy="-1.57079632679 -1.57079632679 0" xyz="0 0 0.240"/>
    <parent link="right_arm_1_link"/>
    <child link="right_arm_2_link"/>
    <axis xyz="0 0 -1"/>
    <limit effort="2160" lower="-2.12" upper="2.12" velocity="0.43633"/>
  </joint>
  <link name="right_arm_2_link">
    <inertial>
      <mass value="0.01"/>
      <origin xyz="0 0 0"/>
      <inertia ixx="0.001" ixy="0.0" ixz="0.0" iyy="0.001" iyz="0.0" izz="0.001"/>
    </inertial>
    <!--
      <xacro:cylinder_inertial radius="0.06" length="0.150" mass="2.0">
        <origin xyz="0 0 0" rpy="0 0 0"/>
      </xacro:cylinder_inertial>
-->
    <visual>
      <geometry>
        <mesh filename="package://lwa4d/arm_2_link.stl"/>
      </geometry>
      <material name="Schunk/Black"/>
    </visual>
    <collision>
      <geometry>
        <mesh filename="package://lwa4d/arm_2_link_collision.stl"/>
      </geometry>
    </collision>
  </link>
  <!-- joint between arm_2_link and arm_3_link -->
  <joint name="right_arm_3_joint" type="revolute">
    <origin rpy="1.57079632679 0 1.57079632679" xyz="0 0 0"/>
    <parent link="right_arm_2_link"/>
    <child link="right_arm_3_link"/>
    <axis xyz="0 0 -1"/>
    <limit effort="815" lower="-3.12159265359" upper="3.12159265359" velocity="0.4189"/>
  </joint>
  <link name="right_arm_3_link">
    <inertial>
      <mass value="0.01"/>
      <origin xyz="0 0 0"/>
      <inertia ixx="0.001" ixy="0.0" ixz="0.0" iyy="0.001" iyz="0.0" izz="0.001"/>
    </inertial>
    <!--
      <xacro:cylinder_inertial radius="0.06" length="0.2" mass="2.0">
        <origin xyz="0.0 0 -0.2" rpy="0 0 0"/>
      </xacro:cylinder_inertial>
-->
    <visual>
      <geometry>
        <mesh filename="package://lwa4d/arm_3_link.stl"/>
      </geometry>
      <material name="Schunk/LightGrey"/>
    </visual>
    <collision>
      <geometry>
        <mesh filename="package://lwa4d/arm_3_link_collision.stl"/>
      </geometry>
    </collision>
  </link>
  <!-- joint between arm_3_link and arm_4_link -->
  <joint name="right_arm_4_joint" type="revolute">
    <origin rpy="-1.57079632679 -1.57079632679 0" xyz="0 0 0.328"/>
    <parent link="right_arm_3_link"/>
    <child link="right_arm_4_link"/>
    <axis xyz="0 0 -1"/>
    <limit effort="815" lower="-2.16" upper="2.16" velocity="0.4189"/>
  </joint>
  <link name="right_arm_4_link">
    <inertial>
      <mass value="0.01"/>
      <origin xyz="0 0 0"/>
      <inertia ixx="0.001" ixy="0.0" ixz="0.0" iyy="0.001" iyz="0.0" izz="0.001"/>
    </inertial>
    <!--
      <xacro:cylinder_inertial radius="0.06" length="0.150" mass="1.2">
        <origin xyz="0 0 0" rpy="0 0 0"/>
      </xacro:cylinder_inertial>
-->
    <visual>
      <geometry>
        <mesh filename="package://lwa4d/arm_4_link.stl"/>
      </geometry>
      <material name="Schunk/Black"/>
    </visual>
    <collision>
      <geometry>
        <mesh filename="package://lwa4d/arm_4_link_collision.stl"/>
      </geometry>
    </collision>
  </link>
  <!-- joint between arm_4_link and arm_5_link -->
  <joint name="right_arm_5_joint" type="revolute">
    <origin rpy="1.57079632679 0 1.57079632679" xyz="0 0 0"/>
    <parent link="right_arm_4_link"/>
    <child link="right_arm_5_link"/>
    <axis xyz="0 0 -1"/>
    <limit effort="207" lower="-3.12159265359" upper="3.12159265359" velocity="0.43633"/>
  </joint>
  <link name="right_arm_5_link">
    <inertial>
      <mass value="0.01"/>
      <origin xyz="0 0 0"/>
      <inertia ixx="0.001" ixy="0.0" ixz="0.0" iyy="0.001" iyz="0.0" izz="0.001"/>
    </inertial>
    <!--
      <xacro:cylinder_inertial radius="0.06" length="0.15" mass="1.2">
        <origin xyz="0 0 -0.18" rpy="0 0 0"/>
      </xacro:cylinder_inertial>
-->
    <visual>
      <geometry>
        <mesh filename="package://lwa4d/arm_5_link.stl"/>
      </geometry>
      <material name="Schunk/LightGrey"/>
    </visual>
    <collision>
      <geometry>
        <mesh filename="package://lwa4d/arm_5_link_collision.stl"/>
      </geometry>
    </collision>
  </link>
  <!-- joint between arm_5_link and arm_6_link -->
  <joint name="right_arm_6_joint" type="revolute">
    <origin rpy="-1.57079632679 -1.57079632679 0" xyz="0 0 0.323"/>
    <parent link="right_arm_5_link"/>
    <child link="right_arm_6_link"/>
    <axis xyz="0 0 1"/>
    <limit effort="150" lower="-2.07" upper="2.07" velocity="1.2566"/>
  </joint>
  <link name="right_arm_6_link">
    <inertial>
      <mass value="0.01"/>
      <origin xyz="0 0 0"/>
      <inertia ixx="0.001" ixy="0.0" ixz="0.0" iyy="0.001" iyz="0.0" izz="0.001"/>
    </inertial>
    <!--
      <xacro:sphere_inertial radius="0.05" mass="1.9">
        <origin xyz="0 0 0" rpy="0 0 0"/>
      </xacro:sphere_inertial>
-->
    <visual>
      <geometry>
        <mesh filename="package://lwa4d/arm_6_link.stl"/>
      </geometry>
      <material name="Schunk/Black"/>
    </visual>
    <collision>
      <geometry>
        <mesh filename="package://lwa4d/arm_6_link_collision.stl"/>
      </geometry>
    </collision>
  </link>
  <!-- joint between arm_6_link and arm_7_link -->
  <joint name="right_arm_7_joint" type="revolute">
    <origin rpy="1.57079632679 0 1.57079632679" xyz="0 0 0"/>
    <parent link="right_arm_6_link"/>
    <child link="right_arm_7_link"/>
    <axis xyz="0 0 1"/>
    <limit effort="150" lower="-2.94" upper="2.94" velocity="1.2566"/>
  </joint>
  <link name="right_arm_7_link">
    <inertial>
      <mass value="0.01"/>
      <origin xyz="0 0 0"/>
      <inertia ixx="0.001" ixy="0.0" ixz="0.0" iyy="0.001" iyz="0.0" izz="0.001"/>
    </inertial>
    <!--
      <xacro:cylinder_inertial radius="0.03" length="0.035" mass="0.05">
        <origin xyz="0 0 0.06" rpy="0 0 0"/>
      </xacro:cylinder_inertial>
-->
    <visual>
      <geometry>
        <mesh filename="package://lwa4d/arm_7_link.stl"/>
      </geometry>
      <material name="Schunk/LightGrey"/>
    </visual>
    <collision>
      <geometry>
        <mesh filename="package://lwa4d/arm_7_link.stl"/>
      </geometry>
    </collision>
  </link>
  <joint name="right_arm_ee_joint" type="fixed">
    <origin rpy="0 0 0" xyz="0 0 0.0824"/>
    <parent link="right_arm_7_link"/>
    <child link="right_arm_ee_link"/>
  </joint>
  <link name="right_arm_ee_link">
    <inertial>
      <mass value="0.01"/>
      <origin xyz="0 0 0"/>
      <inertia ixx="0.001" ixy="0.0" ixz="0.0" iyy="0.001" iyz="0.0" izz="0.001"/>
    </inertial>
  </link>
  <link name="gripper_link">
    <inertial>
      <origin rpy="0 0 0" xyz="-0.0900 -0.0001 -0.0017" />
      <mass value="1.5175" />
      <inertia ixx="0.0013" ixy="-0.0" ixz="0.0" iyy="0.0019" iyz="-0.0" izz="0.0024" />
    </inertial>
    <visual>
      <origin rpy="0 0 0" xyz="0 0 0" />
      <geometry>
        <mesh filename="package://lwa4d/fetch_gripper/gripper_link.dae" />
      </geometry>
    </visual>
    <collision>
      <origin rpy="0 0 0" xyz="0 0 0" />
      <geometry>
        <mesh filename="package://lwa4d/fetch_gripper/gripper_link.STL" />
      </geometry>
    </collision>
  </link>
  <joint name="gripper_axis" type="fixed">
    <origin rpy="0 0 0" xyz="0.16645 0 0" />
    <parent link="right_arm_ee_link" />
    <child link="gripper_link" />
    <axis xyz="0 1 0" />
  </joint>
  <link name="r_gripper_finger_link">
    <inertial>
      <origin rpy="0 0 0" xyz="-0.01 0 0" />
      <mass value="0.0798" />
      <inertia ixx="0.002" ixy="0" ixz="0" iyy="0" iyz="0" izz="0" />
    </inertial>
    <visual>
      <origin rpy="0 0 0" xyz="0 0.101425 0" />
      <geometry>
        <mesh filename="package://lwa4d/fetch_gripper/r_gripper_finger_link.STL" />
      </geometry>
      <material name="">
        <color rgba="0.356 0.361 0.376 1" />
      </material>
    </visual>
    <collision>
      <origin rpy="0 0 0" xyz="0 0.101425 0" />
      <geometry>
        <mesh filename="package://lwa4d/fetch_gripper/r_gripper_finger_link.STL" />
      </geometry>
    </collision>
  </link>
  <joint name="r_gripper_finger_joint" type="prismatic">
    <origin rpy="0 0 0" xyz="0 0.015425 0" />
    <parent link="gripper_link" />
    <child link="r_gripper_finger_link" />
    <axis xyz="0 1 0" />
  <limit effort="60" lower="0.0" upper="0.05" velocity="0.05" /><dynamics damping="100.0" /></joint>
  <link name="l_gripper_finger_link">
    <inertial>
      <origin rpy="0 0 0" xyz="-0.01 0 0" />
      <mass value="0.0798" />
      <inertia ixx="0.002" ixy="0" ixz="0" iyy="0" iyz="0" izz="0" />
    </inertial>
    <visual>
      <origin rpy="0 0 0" xyz="0 -0.101425 0" />
      <geometry>
        <mesh filename="package://lwa4d/fetch_gripper/l_gripper_finger_link.STL" />
      </geometry>
      <material name="">
        <color rgba="0.356 0.361 0.376 1" />
      </material>
    </visual>
    <collision>
      <origin rpy="0 0 0" xyz="0 -0.101425 0" />
      <geometry>
        <mesh filename="package://lwa4d/fetch_gripper/l_gripper_finger_link.STL" />
      </geometry>
    </collision>
  </link>
  <joint name="l_gripper_finger_joint" type="prismatic">
    <origin rpy="0 0 0" xyz="0 -0.015425 0" />
    <parent link="gripper_link" />
    <child link="l_gripper_finger_link" />
    <axis xyz="0 -1 0" />
  <limit effort="60" lower="0.0" upper="0.05" velocity="0.05" /><dynamics damping="100.0" />
  </joint>
</robot>

