<?xml version="1.0" encoding="utf-8"?>
<!-- =================================================================================== -->
<!-- |    This document was autogenerated by xacro from arm_schunk.urdf.xacro          | -->
<!-- |    EDITING THIS FILE BY HAND IS NOT RECOMMENDED                                 | -->
<!-- =================================================================================== -->
<robot name="teodor_2lwa4d" xmlns:xacro="http://www.ros.org/wiki/xacro">
  <material name="Schunk/LightGrey">
    <color rgba="0.7 0.7 0.7 1.0"/>
  </material>
  <material name="Schunk/DarkGrey">
    <color rgba="0.4 0.4 0.4 1.0"/>
  </material>
  <material name="Schunk/Black">
    <color rgba="0.0 0.0 0.0 1.0"/>
  </material>
  <material name="Schunk/DarkGolden">
    <color rgba="0.4 0.4 0.3 1.0"/>
  </material>
  <material name="Schunk/Blue">
    <color rgba="0.0 0.0 0.8 1.0"/>
  </material>
  <link name="world"/>
  <joint name="world_joint" type="fixed">
    <parent link="world"/>
    <child link="base_link"/>
    <origin rpy="0 0 0" xyz="0. 0. 0."/>
  </joint>
  <link name="base_link">
    <visual>
      <origin rpy="0 0 0" xyz="0 0 0"/>
      <geometry>
        <box size="0.01 0.01 0.01"/>
      </geometry>
    </visual>
    <collision>
      <origin rpy="0 0 0" xyz="0 0 0"/>
      <geometry>
        <box size="0.01 0.01 0.01"/>
      </geometry>
    </collision>
  </link>
  <!-- arm mount -->
  <joint name="mount_joint" type="fixed">
    <parent link="base_link"/>
    <child link="mount_link"/>
    <origin rpy="0 0 0" xyz="0. 0. 0."/>
  </joint>
  <link name="mount_link">
    <visual>
      <origin rpy="0 1.57 0" xyz="0 0 0"/>
      <geometry>
        <box size="0.02 0.6 0.6"/>
      </geometry>
      <material name="Schunk/LightGrey">
        <color rgba="0.7 0.7 0.7 1"/>
      </material>
    </visual>
    <collision>
      <origin rpy="0 1.57 0" xyz="0 0 0"/>
      <geometry>
        <box size="0.02 0.6 0.6"/>
      </geometry>
    </collision>
  </link>
  <!-- joint between base_link and lwa4p_extended_connector_link -->
  <joint name="right_arm_podest_joint" type="fixed">
    <origin rpy="0 0 0" xyz="0 0 0"/>
    <parent link="mount_link"/>
    <child link="right_arm_podest_link"/>
  </joint>
  <link name="right_arm_podest_link">
  <!-- Default Mass and Inertia-->
    <inertial>
      <mass value="0.01"/>
      <origin xyz="0 0 0"/>
      <inertia ixx="0.001" ixy="0.0" ixz="0.0" iyy="0.001" iyz="0.0" izz="0.001"/>
    </inertial>
    <visual>
      <geometry>
        <mesh filename="package://lwa4d/arm_podest_link.stl"/>
      </geometry>
      <material name="Schunk/LightGrey"/>
    </visual>
    <collision>
      <geometry>
        <mesh filename="package://lwa4d/arm_podest_link.stl"/>
      </geometry>
    </collision>
  </link>
  <joint name="right_arm_base_joint" type="fixed">
    <origin rpy="0 0 0" xyz="0 0 0.140"/>
    <parent link="right_arm_podest_link"/>
    <child link="right_arm_base_link"/>
  </joint>
  <link name="right_arm_base_link">
  <!--Default Mass and Inertia -->
    <inertial>
      <mass value="0.01"/>
      <origin xyz="0 0 0"/>
      <inertia ixx="0.001" ixy="0.0" ixz="0.0" iyy="0.001" iyz="0.0" izz="0.001"/>
    </inertial>
  </link>
  <!-- joint between arm_base_link and arm_1_link -->
  <joint name="right_arm_1_joint" type="revolute">
    <origin rpy="0 0 0" xyz="0 0 0"/>
    <parent link="right_arm_base_link"/>
    <child link="right_arm_1_link"/>
    <axis xyz="0 0 -1"/>
    <limit effort="216" lower="-3.12159265359" upper="3.12159265359" velocity="0.43633"/>
  </joint>
  <link name="right_arm_1_link">
    <inertial>
      <mass value="3.6"/>
      <origin xyz="0 0 0"/>
      <inertia ixx="0.010" ixy="0.0" ixz="0.0" iyy="0.010" iyz="0.0" izz="0.001"/>
    </inertial>
    <!--
      <xacro:cylinder_inertial radius="0.06" length="0.150" mass="3.6">
          <origin xyz="0 0 0.02" rpy="0 0 0"/>
      </xacro:cylinder_inertial>
-->
    <visual>
      <geometry>
        <mesh filename="package://lwa4d/arm_1_link.stl"/>
      </geometry>
      <material name="Schunk/LightGrey"/>
    </visual>
    <collision>
      <geometry>
        <mesh filename="package://lwa4d/arm_1_link.stl"/>
      </geometry>
    </collision>
  </link>
  <!-- joint between arm_1_link and arm_2_link -->
  <joint name="right_arm_2_joint" type="revolute">
    <origin rpy="-1.57079632679 -1.57079632679 0" xyz="0 0 0.240"/>
    <parent link="right_arm_1_link"/>
    <child link="right_arm_2_link"/>
    <axis xyz="0 0 -1"/>
    <limit effort="216" lower="-2.12" upper="2.12" velocity="0.43633"/>
  </joint>
  <link name="right_arm_2_link">
    <inertial>
      <mass value="2.0"/>
      <origin xyz="0 0 0"/>
      <inertia ixx="0.006" ixy="0.0" ixz="0.0" iyy="0.006" iyz="0.0" izz="0.001"/>
    </inertial>
    <visual>
      <geometry>
        <mesh filename="package://lwa4d/arm_2_link.stl"/>
      </geometry>
      <material name="Schunk/Black"/>
    </visual>
    <collision>
      <geometry>
        <mesh filename="package://lwa4d/arm_2_link_collision.stl"/>
      </geometry>
    </collision>
  </link>
  <!-- joint between arm_2_link and arm_3_link -->
  <joint name="right_arm_3_joint" type="revolute">
    <origin rpy="1.57079632679 0 1.57079632679" xyz="0 0 0"/>
    <parent link="right_arm_2_link"/>
    <child link="right_arm_3_link"/>
    <axis xyz="0 0 -1"/>
    <limit effort="81.5" lower="-3.12159265359" upper="3.12159265359" velocity="0.4189"/>
  </joint>
  <link name="right_arm_3_link">
    <inertial>
      <mass value="2.0"/>
      <origin xyz="0 0 0"/>
      <inertia ixx="0.008" ixy="0.0" ixz="0.0" iyy="0.008" iyz="0.0" izz="0.001"/>
    </inertial>
    <visual>
      <geometry>
        <mesh filename="package://lwa4d/arm_3_link.stl"/>
      </geometry>
      <material name="Schunk/LightGrey"/>
    </visual>
    <collision>
      <geometry>
        <mesh filename="package://lwa4d/arm_3_link_collision.stl"/>
      </geometry>
    </collision>
  </link>
  <!-- joint between arm_3_link and arm_4_link -->
  <joint name="right_arm_4_joint" type="revolute">
    <origin rpy="-1.57079632679 -1.57079632679 0" xyz="0 0 0.328"/>
    <parent link="right_arm_3_link"/>
    <child link="right_arm_4_link"/>
    <axis xyz="0 0 -1"/>
    <limit effort="81.5" lower="-2.16" upper="2.16" velocity="0.4189"/>
  </joint>
  <link name="right_arm_4_link">
    <inertial>
      <mass value="1.2"/>
      <origin xyz="0 0 0"/>
      <inertia ixx="0.003" ixy="0.0" ixz="0.0" iyy="0.003" iyz="0.0" izz="0.0004"/>
    </inertial>
    <visual>
      <geometry>
        <mesh filename="package://lwa4d/arm_4_link.stl"/>
      </geometry>
      <material name="Schunk/Black"/>
    </visual>
    <collision>
      <geometry>
        <mesh filename="package://lwa4d/arm_4_link_collision.stl"/>
      </geometry>
    </collision>
  </link>
  <!-- joint between arm_4_link and arm_5_link -->
  <joint name="right_arm_5_joint" type="revolute">
    <origin rpy="1.57079632679 0 1.57079632679" xyz="0 0 0"/>
    <parent link="right_arm_4_link"/>
    <child link="right_arm_5_link"/>
    <axis xyz="0 0 -1"/>
    <limit effort="20.7" lower="-3.12159265359" upper="3.12159265359" velocity="0.43633"/>
  </joint>
  <link name="right_arm_5_link">
    <inertial>
      <mass value="1.2"/>
      <origin xyz="0 0 -0.18"/>
      <inertia ixx="0.003" ixy="0.0" ixz="0.0" iyy="0.003" iyz="0.0" izz="0.0004"/>
    </inertial>
    <visual>
      <geometry>
        <mesh filename="package://lwa4d/arm_5_link.stl"/>
      </geometry>
      <material name="Schunk/LightGrey"/>
    </visual>
    <collision>
      <geometry>
        <mesh filename="package://lwa4d/arm_5_link_collision.stl"/>
      </geometry>
    </collision>
  </link>
  <!-- joint between arm_5_link and arm_6_link -->
  <joint name="right_arm_6_joint" type="revolute">
    <origin rpy="-1.57079632679 -1.57079632679 0" xyz="0 0 0.323"/>
    <parent link="right_arm_5_link"/>
    <child link="right_arm_6_link"/>
    <axis xyz="0 0 1"/>
    <limit effort="15" lower="-2.07" upper="2.07" velocity="1.2566"/>
  </joint>
  <link name="right_arm_6_link">
    <inertial>
      <mass value="1.9"/>
      <origin xyz="0 0 0"/>
      <inertia ixx="0.002" ixy="0.0" ixz="0.0" iyy="0.002" iyz="0.0" izz="0.002"/>
    </inertial>
    <visual>
      <geometry>
        <mesh filename="package://lwa4d/arm_6_link.stl"/>
      </geometry>
      <material name="Schunk/Black"/>
    </visual>
    <collision>
      <geometry>
        <mesh filename="package://lwa4d/arm_6_link_collision.stl"/>
      </geometry>
    </collision>
  </link>
  <!-- joint between arm_6_link and arm_7_link -->
  <joint name="right_arm_7_joint" type="revolute">
    <origin rpy="1.57079632679 0 1.57079632679" xyz="0 0 0"/>
    <parent link="right_arm_6_link"/>
    <child link="right_arm_7_link"/>
    <axis xyz="0 0 1"/>
    <limit effort="15" lower="-2.94" upper="2.94" velocity="1.2566"/>
  </joint>
  <link name="right_arm_7_link">
    <inertial>
      <mass value="0.05"/>
      <origin xyz="0 0 0.06"/>
      <inertia ixx="0.00002" ixy="0.0" ixz="0.0" iyy="0.00002" iyz="0.0" izz="0.000004"/>
    </inertial>
    <visual>
      <geometry>
        <mesh filename="package://lwa4d/arm_7_link.stl"/>
      </geometry>
      <material name="Schunk/LightGrey"/>
    </visual>
    <collision>
      <geometry>
        <mesh filename="package://lwa4d/arm_7_link.stl"/>
      </geometry>
    </collision>
  </link>
  <joint name="right_arm_ee_joint" type="fixed">
    <origin rpy="0 0 0.0824" xyz="0 0 0.0824"/>
    <parent link="right_arm_7_link"/>
    <child link="right_arm_ee_link"/>
  </joint>
  <link name="right_arm_ee_link">
    <inertial>
      <mass value="1"/>
      <origin xyz="0 0 0"/>
      <inertia ixx="0.01" ixy="0.0" ixz="0.0" iyy="0.01" iyz="0.0" izz="0.01"/>
    </inertial>
  </link>
  <joint name="pg70_podest_joint" type="fixed">
    <origin rpy="0 0 0" xyz="0 0 0"/>
    <parent link="right_arm_ee_link"/>
    <child link="pg70_podest_link"/>
  </joint>
  <link name="pg70_podest_link">
    <inertial>
      <mass value="1"/>
      <origin xyz="0 0 0"/>
      <inertia ixx="0.01" ixy="0.0" ixz="0.0" iyy="0.01" iyz="0.0" izz="0.01"/>
    </inertial>
    <visual>
      <origin rpy="0 3.14159265359 0" xyz="0 0 0"/>
      <geometry>
        <mesh filename="package://lwa4d/arm_base_link.stl"/>
      </geometry>
    </visual>
    <collision>
      <origin rpy="0 3.14159265359 0" xyz="0 0 0"/>
      <geometry>
        <mesh filename="package://lwa4d/arm_base_link.stl"/>
      </geometry>
    </collision>
  </link>
  <joint name="pg70_palm_joint" type="fixed">
    <origin rpy="0 0 0" xyz="0 0 0.0"/>
    <parent link="pg70_podest_link"/>
    <child link="pg70_palm_link"/>
  </joint>
  <link name="pg70_palm_link">
    <inertial>
      <origin rpy="0 0 0" xyz="0 0 0"/>
      <mass value="1"/>
      <inertia ixx="0.01" ixy="0" ixz="0" iyy="0.01" iyz="0" izz="0.01"/>
    </inertial>
    <visual>
      <geometry>
        <mesh filename="package://lwa4d/pg70.dae"/>
      </geometry>
    </visual>
    <collision>
      <geometry>
        <mesh filename="package://lwa4d/pg70.stl"/>
      </geometry>
    </collision>
  </link>
  <joint name="pg70_finger_left_joint" type="prismatic">
    <!-- <origin rpy="0 0 0" xyz="0 -0.015425 0.0789"/> -->
    <origin rpy="0 0 0" xyz="0 0.035 0.0789"/>
    <parent link="pg70_palm_link"/>
    <child link="pg70_finger_left_link"/>
    <axis xyz="0 1 0"/>
    <limit effort="10" lower="-0.001" upper="0.061" velocity="2.0"/>
  </joint>
  <link name="pg70_finger_left_link">
    <inertial>
      <!-- <origin rpy="0 0 0" xyz="-0.01 0 0"/> -->
      <origin rpy="0 0 0" xyz="0 0 0"/>
      <mass value="1"/>
      <inertia ixx="0.01" ixy="0" ixz="0" iyy="0.01" iyz="0" izz="0.01"/>
    </inertial>
    <visual>
      <geometry>
        <!-- <box size="0.04 0.01 0.1"/> -->
        <box size="0.03 0.01 0.07"/>
      </geometry>
      <material name="red">
        <color rgba="1 0 0 1"/>
      </material>
    </visual>
    <collision>
      <geometry>
        <!-- <box size="0.04 0.01 0.1"/> -->
        <box size="0.03 0.01 0.07"/>
      </geometry>
      <material name="red">
        <color rgba="1 0 0 1"/>
      </material>
    </collision>
  </link>
  <joint name="pg70_finger_right_joint" type="prismatic">
    <!-- <origin rpy="0 0 0" xyz="0 0.015425 0.0789"/> -->
    <origin rpy="0 0 0" xyz="0 -0.035 0.0789"/>
    <parent link="pg70_palm_link"/>
    <child link="pg70_finger_right_link"/>
    <axis xyz="0 -1 0"/>
    <!--mimic joint="pg70_finger_left_joint" multiplier="1" offset="0"/-->
    <limit effort="10" lower="-0.001" upper="0.061" velocity="2.0"/>
  </joint>
  <link name="pg70_finger_right_link">
    <inertial>
      <origin rpy="0 0 0" xyz="0 0 0"/>
      <mass value="1"/>
      <inertia ixx="0.01" ixy="0" ixz="0" iyy="0.01" iyz="0" izz="0.01"/>
    </inertial>
    <visual>
      <geometry>
        <!-- <box size="0.04 0.01 0.1"/> -->
        <box size="0.03 0.01 0.07"/>
      </geometry>
      <material name="red">
        <color rgba="1 0 0 1"/>
      </material>
    </visual>
    <collision>
      <geometry>
        <!-- <box size="0.04 0.01 0.1"/> -->
        <box size="0.03 0.01 0.07"/>
      </geometry>
      <material name="red">
        <color rgba="1 0 0 1"/>
      </material>
    </collision>
  </link>
</robot>

