<?xml version="1.0" ?>
<!-- =================================================================================== -->
<!-- |    This document was autogenerated by xacro from max_complete.xacro             | -->
<!-- |    EDITING THIS FILE BY HAND IS NOT RECOMMENDED                                 | -->
<!-- =================================================================================== -->
<robot name="max_complete" xmlns:controller="http://playerstage.sourceforge.net/gazebo/xmlschema/#controller" xmlns:interface="http://playerstage.sourceforge.net/gazebo/xmlschema/#interface" xmlns:sensor="http://playerstage.sourceforge.net/gazebo/xmlschema/#sensor" xmlns:xacro="http://www.ros.org/wiki/xacro">
  <material name="Black">
    <color rgba="0.0 0.0 0.0 1.0"/>
  </material>
  <material name="Black2">
    <color rgba="0.25 0.25 0.25 1.0"/>
  </material>
  <material name="Blue">
    <color rgba="0.0 0.0 0.8 1.0"/>
  </material>
  <material name="Green">
    <color rgba="0.0 0.8 0.0 1.0"/>
  </material>
  <material name="Grey">
    <color rgba="0.7 0.7 0.7 1.0"/>
  </material>
  <material name="Grey2">
    <color rgba="0.9 0.9 0.9 1.0"/>
  </material>
  <material name="Grey3">
    <color rgba="0.5 0.5 0.5 1.0"/>
  </material>
  <material name="Red">
    <color rgba="0.8 0.0 0.0 1.0"/>
  </material>
  <material name="White">
    <color rgba="1.0 1.0 1.0 1.0"/>
  </material>
  <material name="Orange">
    <color rgba="1.0 0.5 0.0 1.0"/>
  </material>
  <material name="Front">
    <color rgba="1.0 0.25 0.0 1.0"/>
  </material>
  <material name="Rear">
    <color rgba="0.0 0.5 1.0 1.0"/>
  </material>
  <!-- Usage example:
  <xacro:include filename="$(find max_manipulator_driver)/urdf/max_manipulator.xacro" />
  <xacro:max_manipulator name="max_manipulator" parent="some_link">
    <origin xyz="0 0 0" rpy="0 0 0" />
  </xacro:max_manipulator>

  The origin of the manipulator is at the bottom center of the turret link. 
  The displacement to the parent link can be given in the origin tag.
-->
  <gazebo>
    <plugin filename="libgazebo_ros_control.so" name="gazebo_ros_control"/>
    <plugin filename="libgazebo_ros_joint_pose_trajectory.so" name="joint_trajectory_plugin">
      <topicName>joint_trajectory</topicName>
      <updateRate>1000.0</updateRate>
    </plugin>
  </gazebo>
  <!--TODO wenn Kamera auf Handgelenk gesteckt wird, aendern sich die Werte-->
  <!-- link, joint, and gazebo definitions of the wheels simulating the track -->
  <!-- Properties -->
  <!-- fictitious link(frame) that is on the ground right below base_link origin, the navigation stack depends on this frame -->
  <link name="base_footprint">
    <inertial>
      <origin rpy="0 0 0" xyz="0 0 0"/>
      <mass value="0.0001"/>
      <inertia ixx="0.0001" ixy="0.0" ixz="0.0" iyy="0.0001" iyz="0.0" izz="0.0001"/>
    </inertial>
    <visual>
      <origin rpy="0 0 0" xyz="0 0 0"/>
      <geometry>
        <box size="0.001 0.001 0.001"/>
      </geometry>
      <material name="Red"/>
    </visual>
    <collision>
      <origin rpy="0 0 0" xyz="0 0 0.151"/>
      <geometry>
        <box size="0.001 0.001 0.001"/>
      </geometry>
    </collision>
  </link>
  <!-- joint for the footprint link -->
  <joint name="base_footprint_joint" type="fixed">
    <origin rpy="0 0 0" xyz="0 0 0.151"/>
    <parent link="base_footprint"/>
    <child link="base_link"/>
  </joint>
  <!-- robot chassis link -->
  <link name="base_link">
    <inertial>
      <origin rpy="0 0 3.14159265359" xyz="-0.1 0 0"/>
      <mass value="50.0"/>
      <inertia ixx="1.0" ixy="0.0" ixz="0.0" iyy="1.0" iyz="0.0" izz="1.0"/>
    </inertial>
    <visual>
      <origin rpy="1.57079632679 0 3.14159265359" xyz="0 0 0"/>
      <geometry>
        <mesh filename="package://telerob/chassis.stl" scale="0.001 0.001 0.001"/>
      </geometry>
      <material name="Grey3"/>
    </visual>
    <collision>
      <origin rpy="0 0 3.14159265359" xyz="0 0 0.105"/>
      <geometry>
        <box size="0.65 0.27 0.20"/>
      </geometry>
    </collision>
  </link >
  <!-- flipper macros -->
  <!-- link definition -->
  <!-- link name="actuator_0_link">
    <inertial>
      <origin rpy="0 0 0" xyz="0 0 0"/>
      <mass value="0.1"/>
      <inertia ixx="1.0" ixy="0.0" ixz="0.0" iyy="1.0" iyz="0.0" izz="1.0"/>
    </inertial>
    <visual>
      <origin rpy="1.57079632679 3.14159265359 3.14159265359" xyz="0 0 0"/>
      <geometry>
        <mesh filename="package://telerob/flipper_fl.stl" scale="0.001 0.001 0.001"/>
      </geometry>
      <material name="Black2"/>
    </visual>
    <collision>
      <geometry>
        <box size="0.01 0.01 0.01"/>
      </geometry>
    </collision>
  </link -->
  <!-- joint definition -->
  <!--joint name="actuator_0_joint" type="revolute">
    <origin xyz="0.205 0 0.085"/>
    <axis xyz="0 1 0"/>
    <anchor xyz="0 0 0"/>
    <limit effort="100" lower="-1.57079632679" upper="1.3962634016" velocity="0.262745098"/>
    <parent link="base_link"/>
    <child link="actuator_0_link"/>
  </joint>
  <gazebo reference="actuator_0_link">
    <mu1>0.0</mu1>
    <mu2>0.0</mu2>
    <kp value="1000000.0"/>
    <kd value="1.0"/>
    <material>Gazebo/Blue</material>
    <turnGravityOff>false</turnGravityOff>
  </gazebo-->
  <!-- link definition -->
  <!--link name="actuator_1_link">
    <inertial>
      <origin rpy="0 0 0" xyz="0 0 0"/>
      <mass value="0.1"/>
      <inertia ixx="1.0" ixy="0.0" ixz="0.0" iyy="1.0" iyz="0.0" izz="1.0"/>
    </inertial>
    <visual>
      <origin rpy="1.57079632679 3.14159265359 3.14159265359" xyz="0 0 0"/>
      <geometry>
        <mesh filename="package://telerob/flipper_fr.stl" scale="0.001 0.001 0.001"/>
      </geometry>
      <material name="Black2"/>
    </visual>
    <collision>
      <geometry>
        <box size="0.01 0.01 0.01"/>
      </geometry>
    </collision>
  </link-->
  <!-- joint definition -->
  <!--joint name="actuator_1_joint" type="revolute">
    <origin xyz="0.205 0 0.085"/>
    <axis xyz="0 1 0"/>
    <anchor xyz="0 0 0"/>
    <limit effort="100" lower="-1.57079632679" upper="1.3962634016" velocity="0.262745098"/>
    <parent link="base_link"/>
    <child link="actuator_1_link"/>
  </joint>
  <gazebo reference="actuator_1_link">
    <mu1>0.0</mu1>
    <mu2>0.0</mu2>
    <kp value="1000000.0"/>
    <kd value="1.0"/>
    <material>Gazebo/Blue</material>
    <turnGravityOff>false</turnGravityOff>
  </gazebo-->
  <!-- link definition -->
  <!--link name="actuator_2_link">
    <inertial>
      <origin rpy="0 0 0" xyz="0 0 0"/>
      <mass value="0.1"/>
      <inertia ixx="1.0" ixy="0.0" ixz="0.0" iyy="1.0" iyz="0.0" izz="1.0"/>
    </inertial>
    <visual>
      <origin rpy="1.57079632679 3.14159265359 3.14159265359" xyz="0 0 0"/>
      <geometry>
        <mesh filename="package://telerob/flipper_rl.stl" scale="0.001 0.001 0.001"/>
      </geometry>
      <material name="Black2"/>
    </visual>
    <collision>
      <geometry>
        <box size="0.01 0.01 0.01"/>
      </geometry>
    </collision>
  </link-->
  <!-- joint definition -->
  <!--joint name="actuator_2_joint" type="revolute">
    <origin xyz="-0.205 0 0.085"/>
    <axis xyz="0 -1 0"/>
    <anchor xyz="0 0 0"/>
    <limit effort="100" lower="-1.57079632679" upper="1.3962634016" velocity="0.262745098"/>
    <parent link="base_link"/>
    <child link="actuator_2_link"/>
  </joint>
  <gazebo reference="actuator_2_link">
    <mu1>0.0</mu1>
    <mu2>0.0</mu2>
    <kp value="1000000.0"/>
    <kd value="1.0"/>
    <material>Gazebo/Blue</material>
    <turnGravityOff>false</turnGravityOff>
  </gazebo-->
  <!-- link definition -->
  <!--link name="actuator_3_link">
    <inertial>
      <origin rpy="0 0 0" xyz="0 0 0"/>
      <mass value="0.1"/>
      <inertia ixx="1.0" ixy="0.0" ixz="0.0" iyy="1.0" iyz="0.0" izz="1.0"/>
    </inertial>
    <visual>
      <origin rpy="1.57079632679 3.14159265359 3.14159265359" xyz="0 0 0"/>
      <geometry>
        <mesh filename="package://telerob/flipper_rr.stl" scale="0.001 0.001 0.001"/>
      </geometry>
      <material name="Black2"/>
    </visual>
    <collision>
      <geometry>
        <box size="0.01 0.01 0.01"/>
      </geometry>
    </collision>
  </link-->
  <!-- joint definition -->
  <!--joint name="actuator_3_joint" type="revolute">
    <origin xyz="-0.205 0 0.085"/>
    <axis xyz="0 -1 0"/>
    <anchor xyz="0 0 0"/>
    <limit effort="100" lower="-1.57079632679" upper="1.3962634016" velocity="0.262745098"/>
    <parent link="base_link"/>
    <child link="actuator_3_link"/>
  </joint>
  <gazebo reference="actuator_3_link">
    <mu1>0.0</mu1>
    <mu2>0.0</mu2>
    <kp value="1000000.0"/>
    <kd value="1.0"/>
    <material>Gazebo/Blue</material>
    <turnGravityOff>false</turnGravityOff>
  </gazebo-->
  <link name="manipulator_payload_link">
    <visual>
      <origin rpy="0 0 0" xyz="0.0 0.0 0.0"/>
      <geometry>
        <box size="0.0 0.0 0.0"/>
      </geometry>
    </visual>
    <collision>
      <origin rpy="0 0 0" xyz="0.0 0.0 0.0"/>
      <geometry>
        <box size="0.0 0.0 0.0"/>
      </geometry>
    </collision>
  </link>
  <joint name="base_to_payload_joint" type="fixed">
    <parent link="base_link"/>
    <child link="manipulator_payload_link"/>
    <origin rpy="0 0 0" xyz="0 0 0"/>
  </joint>
  <joint name="manipulator_payload_joint" type="fixed">
    <parent link="manipulator_payload_link"/>
    <child link="manipulator_base_link"/>
    <origin rpy="0 0 0" xyz="0.225 0.0 0.21"/>
  </joint>
  <link name="manipulator_base_link">
    <visual>
      <origin rpy="0 0 0" xyz="0 0 0"/>
      <geometry>
        <cylinder length="0.02" radius="0.09"/>
      </geometry>
      <material name="lightGrey">
        <color rgba="0.6 0.6 0.6 1"/>
      </material>
    </visual>
    <collision>
      <origin rpy="0 0 0" xyz="0 0 0"/>
      <geometry>
        <cylinder length="0.02" radius="0.09"/>
      </geometry>
    </collision>
    <inertial>
      <origin rpy="0 0 0" xyz="0 0 0"/>
      <mass value="0.0001"/>
      <inertia ixx="1.0" ixy="0.0" ixz="0.0" iyy="1.0" iyz="0.0" izz="1.0"/>
    </inertial>
  </link>
  <joint name="turretTurn_joint" type="revolute">
    <parent link="manipulator_base_link"/>
    <child link="turret_link"/>
    <origin rpy="0 0 0" xyz="0 0 0"/>
    <axis xyz="0 0 1"/>
    <limit effort="0.0174532925199" lower="-3.66519142919" upper="3.66519142919" velocity="0.628318530718"/>
  </joint>
  <link name="turret_link">
    <visual>
      <origin rpy="0 0 0" xyz="0.004 0.02135 0.126"/>
      <geometry>
        <box size="0.238 0.1857 0.252"/>
      </geometry>
      <material name="grey">
        <color rgba="0.5 0.5 0.5 1"/>
      </material>
    </visual>
    <collision>
      <origin rpy="0 0 0" xyz="0.004 0.02135 0.126"/>
      <geometry>
        <box size="0.238 0.1857 0.252"/>
      </geometry>
    </collision>
    <inertial>
      <origin rpy="0 0 0" xyz="0.004 0.02135 0.126"/>
      <mass value="1.0"/>
      <inertia ixx="1.0" ixy="0.0" ixz="0.0" iyy="1.0" iyz="0.0" izz="1.0"/>
    </inertial>
  </link>
  <joint name="turret_cam_case_joint" type="fixed">
    <parent link="turret_link"/>
    <child link="turret_cam_case_link"/>
    <origin rpy="0 0 0" xyz="0.0 0.0 0.252"/>
  </joint>
  <link name="turret_cam_case_link">
    <visual>
      <origin rpy="0 0 0" xyz="-0.035 0.0285 0.025"/>
      <geometry>
        <box size="0.12 0.065 0.05"/>
      </geometry>
      <material name="darkGrey">
        <color rgba="0.3 0.3 0.3 1"/>
      </material>
    </visual>
    <collision>
      <origin rpy="0 0 0" xyz="-0.035 0.0285 0.025"/>
      <geometry>
        <box size="0.12 0.065 0.05"/>
      </geometry>
    </collision>
    <inertial>
      <origin rpy="0 0 0" xyz="-0.035 0.0285 0.025"/>
      <mass value="1.0"/>
      <inertia ixx="1.0" ixy="0.0" ixz="0.0" iyy="1.0" iyz="0.0" izz="1.0"/>
    </inertial>
  </link>
  <joint name="upperArmTilt_joint" type="revolute">
    <parent link="turret_link"/>
    <child link="shoulder_link"/>
    <origin rpy="0 0 0" xyz="0.06 -0.081 0.155"/>
    <axis xyz="0 1 0"/>
    <limit effort="0.0174532925199" lower="-2.72271363311" upper="1.0471975512" velocity="0.418879020479"/>
  </joint>
  <link name="shoulder_link">
    <visual>
      <origin rpy="0 0 0" xyz="0.0115 0 0"/>
      <geometry>
        <box size="0.155 0.0822 0.110"/>
      </geometry>
      <material name="darkGrey">
        <color rgba="0.3 0.3 0.3 1"/>
      </material>
    </visual>
    <collision>
      <origin rpy="0 0 0" xyz="0.0115 0 0"/>
      <geometry>
        <box size="0.155 0.0822 0.110"/>
      </geometry>
    </collision>
    <inertial>
      <origin rpy="0 0 0" xyz="0.0115 0 0"/>
      <mass value="1.0"/>
      <inertia ixx="1.0" ixy="0.0" ixz="0.0" iyy="1.0" iyz="0.0" izz="1.0"/>
    </inertial>
  </link>
  <joint name="telescope_fixed_joint" type="fixed">
    <parent link="shoulder_link"/>
    <child link="telescope_link"/>
    <origin rpy="0 0 0" xyz="0.089 0.0 0.0"/>
  </joint>
  <link name="telescope_link">
    <visual>
      <origin rpy="0 0 0" xyz="0.155 0 0"/>
      <geometry>
        <box size="0.31 0.0741 0.0744"/>
      </geometry>
      <material name="lightGrey"/>
    </visual>
    <collision>
      <origin rpy="0 0 0" xyz="0.155 0 0"/>
      <geometry>
        <box size="0.31 0.0741 0.0744"/>
      </geometry>
    </collision>
    <inertial>
      <origin rpy="0 0 0" xyz="0.155 0 0"/>
      <mass value="1.0"/>
      <inertia ixx="1.0" ixy="0.0" ixz="0.0" iyy="1.0" iyz="0.0" izz="1.0"/>
    </inertial>
  </link>
  <joint name="telescope_joint" type="prismatic">
    <parent link="shoulder_link"/>
    <child link="upperArm_link"/>
    <origin rpy="0 0 0" xyz="0.089 0.0 0.0"/>
    <axis xyz="1 0 0"/>
    <limit effort="1.0" lower="-0.0005" upper="0.2905" velocity="0.065"/>
  </joint>
  <link name="upperArm_link">
    <visual>
      <origin rpy="0 0 0" xyz="0.286 0 0"/>
      <geometry>
        <box size="0.572 0.0741 0.0801"/>
      </geometry>
      <material name="grey"/>
    </visual>
    <collision>
      <origin rpy="0 0 0" xyz="0.286 0 0"/>
      <geometry>
        <box size="0.572 0.0741 0.0801"/>
      </geometry>
    </collision>
    <inertial>
      <origin rpy="0 0 0" xyz="0.286 0 0"/>
      <mass value="1.0"/>
      <inertia ixx="1.0" ixy="0.0" ixz="0.0" iyy="1.0" iyz="0.0" izz="1.0"/>
    </inertial>
  </link>
  <joint name="lowerArmTilt_joint" type="revolute">
    <parent link="upperArm_link"/>
    <child link="lowerArmTilt_link"/>
    <origin rpy="0 0 0" xyz="0.532 0.081 0.0"/>
    <axis xyz="0 1 0"/>
    <limit effort="0.0174532925199" lower="-2.96705972839" upper="2.96705972839" velocity="0.628318530718"/>
  </joint>
  <link name="lowerArmTilt_link">
    <visual>
      <origin rpy="0 0 0" xyz="0.0623 0.0117 0.005"/>
      <geometry>
        <box size="0.2046 0.1034 0.09"/>
      </geometry>
      <material name="darkGrey"/>
    </visual>
    <collision>
      <origin rpy="0 0 0" xyz="0.0623 0.0117 0.005"/>
      <geometry>
        <box size="0.2046 0.1034 0.09"/>
      </geometry>
    </collision>
    <inertial>
      <origin rpy="0 0 0" xyz="0.0623 0.0117 0.005"/>
      <mass value="1.0"/>
      <inertia ixx="1.0" ixy="0.0" ixz="0.0" iyy="1.0" iyz="0.0" izz="1.0"/>
    </inertial>
  </link>
  <joint name="lowerArmTurn_joint" type="revolute">
    <parent link="lowerArmTilt_link"/>
    <child link="lowerArmTurn_link"/>
    <origin rpy="0 0 0" xyz="0.1646 0.0 0.0"/>
    <axis xyz="1 0 0"/>
    <limit effort="0.0174532925199" lower="-3.66519142919" upper="3.66519142919" velocity="1.3962634016"/>
  </joint>
  <link name="lowerArmTurn_link">
    <visual>
      <origin rpy="0 0 0" xyz="0.247 -0.00745 0"/>
      <geometry>
        <box size="0.494 0.1195 0.06"/>
      </geometry>
      <material name="grey"/>
    </visual>
    <collision>
      <origin rpy="0 0 0" xyz="0.247 -0.00745 0"/>
      <geometry>
        <box size="0.494 0.1195 0.06"/>
      </geometry>
    </collision>
    <inertial>
      <origin rpy="0 0 0" xyz="0.247 -0.00745 0"/>
      <mass value="1.0"/>
      <inertia ixx="1.0" ixy="0.0" ixz="0.0" iyy="1.0" iyz="0.0" izz="1.0"/>
    </inertial>
  </link>
  <joint name="gripperTilt_joint" type="revolute">
    <parent link="lowerArmTurn_link"/>
    <child link="gripperTilt_link"/>
    <origin rpy="0 0 0" xyz="0.464 0.0 0.0"/>
    <axis xyz="0 1 0"/>
    <limit effort="0.0174532925199" lower="-2.26892802759" upper="2.26892802759" velocity="1.3962634016"/>
  </joint>
  <link name="gripperTilt_link">
    <visual>
      <origin rpy="0 0 0" xyz="0.025 -0.008 0.0073"/>
      <geometry>
        <box size="0.168 0.076 0.088"/>
      </geometry>
      <material name="darkGrey"/>
    </visual>
    <collision>
      <origin rpy="0 0 0" xyz="0.025 -0.008 0.0073"/>
      <geometry>
        <box size="0.168 0.076 0.088"/>
      </geometry>
    </collision>
    <inertial>
      <origin rpy="0 0 0" xyz="0.025 -0.008 0.0073"/>
      <mass value="1.0"/>
      <inertia ixx="1.0" ixy="0.0" ixz="0.0" iyy="1.0" iyz="0.0" izz="1.0"/>
    </inertial>
  </link>
  <joint name="gripperTurn_joint" type="continuous">
    <parent link="gripperTilt_link"/>
    <child link="gripperTurn_link"/>
    <origin rpy="0 0 0" xyz="0.109 0.0 0.0"/>
    <axis xyz="1 0 0"/>
    <limit effort="0.0174532925199" lower="-9999" upper="9999" velocity="1.3962634016"/>
  </joint>
  <link name="gripperTurn_link">
    <visual>
      <origin rpy="0 0 0" xyz="0.0315 0 -0.01705"/>
      <geometry>
        <box size="0.063 0.098 0.0709"/>
      </geometry>
      <material name="grey"/>
    </visual>
    <collision>
      <origin rpy="0 0 0" xyz="0.0315 0 -0.01705"/>
      <geometry>
        <box size="0.063 0.098 0.0709"/>
      </geometry>
    </collision>
    <inertial>
      <origin rpy="0 0 0" xyz="0.0315 0 -0.01705"/>
      <mass value="1.0"/>
      <inertia ixx="1.0" ixy="0.0" ixz="0.0" iyy="1.0" iyz="0.0" izz="1.0"/>
    </inertial>
  </link>
  <!-- gripper dummy:
  <joint name="gripperDummy_joint" type="fixed">
      <parent link="gripperTurn_link"/>
      <child link="gripperDummy_link"/>
      <origin xyz="0.063 0.0 0.0" rpy="0 0 0" />
  </joint>

  <xacro:gen_link name="gripperDummy_link" mass="1.0">
      <origin xyz="${0.112/2} 0 ${-0.0184 + (0.0184+0.0525)/2}" rpy="0 0 0"/>
      <geometry>
          <box size="0.112 ${0.01 + 2*0.04} ${0.0184+0.0525}" />
      </geometry>
      <material name="blue">
          <color rgba="0.0 0.0 0.8 1"/>
      </material>
  </xacro:gen_link>
  -->
  <!-- When the gripper is opened, it moves forwards/backwards in addition to
       the lateral movement. This is modeled with a prismatic joint 
       (gripperForward_joint). The gripperForward_joint models the line segment
       depicted as 'a' in gripper.svg. Therefore, its maximum length is 60mm at
       a gripper width of 10mm and its minimum length is about 33mm at the 
       maximum gripper width of 120mm.
       The gripperForwardJoint is located 20mm in x-direction of the 
       gripperTurn_joint ('f' in gripper.svg).
  -->
  <joint name="gripperForward_joint" type="prismatic">
    <parent link="gripperTurn_link"/>
    <child link="gripperForward_link"/>
    <origin rpy="0 0 0" xyz="0.02 0 0"/>
    <axis xyz="1 0 0"/>
    <limit effort="1.0" lower="0.03" upper="0.06" velocity="0.08"/>
  </joint>
  <link name="gripperForward_link">
    <visual>
      <origin rpy="0 0 0" xyz="-0.03 0 0"/>
      <geometry>
        <box size="0.06 0.1 0.024"/>
      </geometry>
      <material name="grey"/>
    </visual>
    <collision>
      <origin rpy="0 0 0" xyz="-0.03 0 0"/>
      <geometry>
        <box size="0.06 0.1 0.024"/>
      </geometry>
    </collision>
    <inertial>
      <origin rpy="0 0 0" xyz="-0.03 0 0"/>
      <mass value="1.0"/>
      <inertia ixx="1.0" ixy="0.0" ixz="0.0" iyy="1.0" iyz="0.0" izz="1.0"/>
    </inertial>
  </link>
  <joint name="gripperJawRight_joint" type="prismatic">
    <parent link="gripperForward_link"/>
    <child link="gripperJawRight_link"/>
    <origin rpy="0 0 0" xyz="0 0 0"/>
    <axis xyz="0 -1 0"/>
    <limit effort="1.0" lower="0.0" upper="0.06" velocity="0.0085"/>
  </joint>
  <link name="gripperJawRight_link">
    <visual>
      <origin rpy="0 0 0" xyz="0.048 -0.02 0.0"/>
      <geometry>
        <box size="0.096 0.04 0.024"/>
      </geometry>
      <material name="darkGrey"/>
    </visual>
    <collision>
      <origin rpy="0 0 0" xyz="0.048 -0.02 0.0"/>
      <geometry>
        <box size="0.096 0.04 0.024"/>
      </geometry>
    </collision>
    <inertial>
      <origin rpy="0 0 0" xyz="0.048 -0.02 0.0"/>
      <mass value="1.0"/>
      <inertia ixx="1.0" ixy="0.0" ixz="0.0" iyy="1.0" iyz="0.0" izz="1.0"/>
    </inertial>
  </link>
  <joint name="gripperWidth_joint" type="prismatic">
    <parent link="gripperJawRight_link"/>
    <child link="gripperJawLeft_link"/>
    <origin rpy="0 0 0" xyz="0 0 0.0"/>
    <axis xyz="0 1 0"/>
    <limit effort="1.0" lower="0.0" upper="0.12" velocity="0.017"/>
  </joint>
  <link name="gripperJawLeft_link">
    <visual>
      <origin rpy="0 0 0" xyz="0.048 0.02 0.0"/>
      <geometry>
        <box size="0.096 0.04 0.024"/>
      </geometry>
      <material name="darkGrey"/>
    </visual>
    <collision>
      <origin rpy="0 0 0" xyz="0.048 0.02 0.0"/>
      <geometry>
        <box size="0.096 0.04 0.024"/>
      </geometry>
    </collision>
    <inertial>
      <origin rpy="0 0 0" xyz="0.048 0.02 0.0"/>
      <mass value="1.0"/>
      <inertia ixx="1.0" ixy="0.0" ixz="0.0" iyy="1.0" iyz="0.0" izz="1.0"/>
    </inertial>
  </link>
  <joint name="gripperTCP_joint" type="fixed">
    <parent link="gripperForward_link"/>
    <child link="gripperTCP_link"/>
    <origin rpy="0 0 0" xyz="0.056 0 0.0"/>
    <!-- The gripperTCP_joint is in the center of the gripper. 
           That is at equal distance to both gripper jaws and 4cm back from
           the tip. -->
  </joint>
  <link name="gripperTCP_link">
    <visual>
      <!-- The visual is at the tcp. -->
      <origin rpy="0 0 0" xyz="0 0 0"/>
      <geometry>
        <box size="0.01 0.01 0.01"/>
      </geometry>
      <material name="green">
        <color rgba="0.0 1.0 0.0 1"/>
      </material>
    </visual>
    <collision>
      <!-- The gripperTCP_link shall never cause collisions. The 
                 collision geometry is moved backwards to be always within the 
                 manipulator.
                 -->
      <origin rpy="0 0 0" xyz="-0.096 0.0 0.0"/>
      <geometry>
        <box size="0.001 0.001 0.001"/>
      </geometry>
    </collision>
  </link>
  <transmission name="turretTurn_trans">
    <type>transmission_interface/SimpleTransmission</type>
    <joint name="turretTurn_joint">
      <hardwareInterface>EffortJointInterface</hardwareInterface>
    </joint>
    <actuator name="turretTurn_motor">
      <mechanicalReduction>1</mechanicalReduction>
    </actuator>
  </transmission>
  <transmission name="upperArmTilt_trans">
    <type>transmission_interface/SimpleTransmission</type>
    <joint name="upperArmTilt_joint">
      <hardwareInterface>EffortJointInterface</hardwareInterface>
    </joint>
    <actuator name="upperArmTilt_motor">
      <mechanicalReduction>1</mechanicalReduction>
    </actuator>
  </transmission>
  <transmission name="telescope_trans">
    <type>transmission_interface/SimpleTransmission</type>
    <joint name="telescope_joint">
      <hardwareInterface>EffortJointInterface</hardwareInterface>
    </joint>
    <actuator name="telescope_motor">
      <mechanicalReduction>1</mechanicalReduction>
    </actuator>
  </transmission>
  <transmission name="lowerArmTilt_trans">
    <type>transmission_interface/SimpleTransmission</type>
    <joint name="lowerArmTilt_joint">
      <hardwareInterface>EffortJointInterface</hardwareInterface>
    </joint>
    <actuator name="lowerArmTilt_motor">
      <mechanicalReduction>1</mechanicalReduction>
    </actuator>
  </transmission>
  <transmission name="lowerArmTurn_trans">
    <type>transmission_interface/SimpleTransmission</type>
    <joint name="lowerArmTurn_joint">
      <hardwareInterface>EffortJointInterface</hardwareInterface>
    </joint>
    <actuator name="lowerArmTurn_motor">
      <mechanicalReduction>1</mechanicalReduction>
    </actuator>
  </transmission>
  <transmission name="gripperTilt_trans">
    <type>transmission_interface/SimpleTransmission</type>
    <joint name="gripperTilt_joint">
      <hardwareInterface>EffortJointInterface</hardwareInterface>
    </joint>
    <actuator name="gripperTilt_motor">
      <mechanicalReduction>1</mechanicalReduction>
    </actuator>
  </transmission>
  <transmission name="gripperTurn_trans">
    <type>transmission_interface/SimpleTransmission</type>
    <joint name="gripperTurn_joint">
      <hardwareInterface>EffortJointInterface</hardwareInterface>
    </joint>
    <actuator name="gripperTurn_motor">
      <mechanicalReduction>1</mechanicalReduction>
    </actuator>
  </transmission>
  <transmission name="gripperForward_trans">
    <type>transmission_interface/SimpleTransmission</type>
    <joint name="gripperForward_joint">
      <hardwareInterface>EffortJointInterface</hardwareInterface>
    </joint>
    <actuator name="gripperForward_motor">
      <mechanicalReduction>1</mechanicalReduction>
    </actuator>
  </transmission>
  <transmission name="gripperJawRight_trans">
    <type>transmission_interface/SimpleTransmission</type>
    <joint name="gripperJawRight_joint">
      <hardwareInterface>EffortJointInterface</hardwareInterface>
    </joint>
    <actuator name="gripperJawRight_motor">
      <mechanicalReduction>1</mechanicalReduction>
    </actuator>
  </transmission>
  <transmission name="gripperJawLeft_trans">
    <type>transmission_interface/SimpleTransmission</type>
    <joint name="gripperJawLeft_joint">
      <hardwareInterface>EffortJointInterface</hardwareInterface>
    </joint>
    <actuator name="gripperJawLeft_motor">
      <mechanicalReduction>1</mechanicalReduction>
    </actuator>
  </transmission>
</robot>
